Workbook

Sheet Dashboard
B2: Global Top Companies Intelligence Database
B3: Phase 1: Top 50 Economies | Executive Dashboard
B4: Last Updated: 2026-07-18
B6: Coverage Summary | E6: Companies per Country
B7: Total Countries Covered | C7: 50 | E7: United States | F7: =COUNTIF('Global Master Database'!$C$2:$C$266,E7) -> 0
B8: Total Companies Profiled | C8: 264 | E8: China | F8: =COUNTIF('Global Master Database'!$C$2:$C$266,E8) -> 0
B9: Total Industries Represented | C9: 56 | E9: Japan | F9: =COUNTIF('Global Master Database'!$C$2:$C$266,E9) -> 0
B10: Fields per Company | C10: 22 | E10: Germany | F10: =COUNTIF('Global Master Database'!$C$2:$C$266,E10) -> 0
B11: Fully Verified Fields | C11: 17 of 22 (stable facts) | E11: India | F11: =COUNTIF('Global Master Database'!$C$2:$C$266,E11) -> 0
B12: Fields Pending Live Verification | C12: 5 of 22 (CEO, financials, rank) | E12: United Kingdom | F12: =COUNTIF('Global Master Database'!$C$2:$C$266,E12) -> 0
E13: France | F13: =COUNTIF('Global Master Database'!$C$2:$C$266,E13) -> 0
B14: Industry Distribution (# Companies) | E14: Italy | F14: =COUNTIF('Global Master Database'!$C$2:$C$266,E14) -> 0
B15: Aerospace | C15: =COUNTIF('Global Master Database'!$E$2:$E$266,B15) -> 1 | E15: Brazil | F15: =COUNTIF('Global Master Database'!$C$2:$C$266,E15) -> 0
B16: Agriculture | C16: =COUNTIF('Global Master Database'!$E$2:$E$266,B16) -> 1 | E16: Canada | F16: =COUNTIF('Global Master Database'!$C$2:$C$266,E16) -> 0
B17: Automotive | C17: =COUNTIF('Global Master Database'!$E$2:$E$266,B17) -> 9 | E17: Russia | F17: =COUNTIF('Global Master Database'!$C$2:$C$266,E17) -> 0
B18: Aviation | C18: =COUNTIF('Global Master Database'!$E$2:$E$266,B18) -> 6 | E18: South Korea | F18: =COUNTIF('Global Master Database'!$C$2:$C$266,E18) -> 0
B19: Aviation/Infrastructure | C19: =COUNTIF('Global Master Database'!$E$2:$E$266,B19) -> 1 | E19: Australia | F19: =COUNTIF('Global Master Database'!$C$2:$C$266,E19) -> 0
B20: Banking | C20: =COUNTIF('Global Master Database'!$E$2:$E$266,B20) -> 63 | E20: Spain | F20: =COUNTIF('Global Master Database'!$C$2:$C$266,E20) -> 0
B21: Beverages | C21: =COUNTIF('Global Master Database'!$E$2:$E$266,B21) -> 4 | E21: Mexico | F21: =COUNTIF('Global Master Database'!$C$2:$C$266,E21) -> 0
B22: Beverages/Retail | C22: =COUNTIF('Global Master Database'!$E$2:$E$266,B22) -> 1 | E22: Indonesia | F22: =COUNTIF('Global Master Database'!$C$2:$C$266,E22) -> 0
B23: Cement | C23: =COUNTIF('Global Master Database'!$E$2:$E$266,B23) -> 1 | E23: Netherlands | F23: =COUNTIF('Global Master Database'!$C$2:$C$266,E23) -> 0
B24: Chemicals | C24: =COUNTIF('Global Master Database'!$E$2:$E$266,B24) -> 4 | E24: Saudi Arabia | F24: =COUNTIF('Global Master Database'!$C$2:$C$266,E24) -> 0
B25: Chemicals/Energy | C25: =COUNTIF('Global Master Database'!$E$2:$E$266,B25) -> 1 | E25: Turkey | F25: =COUNTIF('Global Master Database'!$C$2:$C$266,E25) -> 0
B26: Chemicals/Manufacturing | C26: =COUNTIF('Global Master Database'!$E$2:$E$266,B26) -> 1 | E26: Switzerland | F26: =COUNTIF('Global Master Database'!$C$2:$C$266,E26) -> 0
... B56: Pharmaceuticals | C56: =COUNTIF('Global Master Database'!$E$2:$E$266,B56) -> 7 | E56: Qatar | F56: =COUNTIF('Global Master Database'!$C$2:$C$266,E56) -> 0
B57: Pharmaceuticals/Conglomerate | C57: =COUNTIF('Global Master Database'!$E$2:$E$266,B57) -> 1
B58: Renewable Energy | C58: =COUNTIF('Global Master Database'!$E$2:$E$266,B58) -> 1
B59: Retail | C59: =COUNTIF('Global Master Database'!$E$2:$E$266,B59) -> 5
B60: Semiconductors | C60: =COUNTIF('Global Master Database'!$E$2:$E$266,B60) -> 4
B61: Shipping | C61: =COUNTIF('Global Master Database'!$E$2:$E$266,B61) -> 1
B62: Software | C62: =COUNTIF('Global Master Database'!$E$2:$E$266,B62) -> 1
B63: Steel | C63: =COUNTIF('Global Master Database'!$E$2:$E$266,B63) -> 4
B64: Technology | C64: =COUNTIF('Global Master Database'!$E$2:$E$266,B64) -> 5
B65: Technology/Media | C65: =COUNTIF('Global Master Database'!$E$2:$E$266,B65) -> 1
B66: Telecommunications | C66: =COUNTIF('Global Master Database'!$E$2:$E$266,B66) -> 20
B67: Telecommunications/Investment | C67: =COUNTIF('Global Master Database'!$E$2:$E$266,B67) -> 1
B68: Telecommunications/Technology | C68: =COUNTIF('Global Master Database'!$E$2:$E$266,B68) -> 1
... B70: Utilities/Energy | C70: =COUNTIF('Global Master Database'!$E$2:$E$266,B70) -> 1
B72: Executive Summary
B73: This workbook profiles 264 leading companies across the world's Top 50 economies (by GDP), selected for revenue scale, market capitalization, employment, and strategic national importance. Company identity, HQ, industry classification, and founding data are drawn from stable, well-documented public facts. CEO names and financial figures (revenue, net income, market cap, Fortune Global 500 rank) are marked 'Verification Pending' rather than estimated, since these change quarterly/annually and were not confirmed against a live source at build time. Recommended next step: run a targeted verification pass (financial filings, investor relations pages) before using pending fields in investment or academic analysis. This is Phase 1 of a workbook designed to scale to all ~195 countries and 10,000+ companies.

Sheet Country Index
A1: Country Index
A2: Click a country to jump to its worksheet. Phase 1 covers the Top 50 economies by GDP.
A4: # | B4: Country | C4: # Companies
A5: 1 | B5: United States | C5: 8
A6: 2 | B6: China | C6: 8
A7: 3 | B7: Japan | C7: 7
A8: 4 | B8: Germany | C8: 7
A9: 5 | B9: India | C9: 7
A10: 6 | B10: United Kingdom | C10: 6
A11: 7 | B11: France | C11: 6
A12: 8 | B12: Italy | C12: 5
A13: 9 | B13: Brazil | C13: 5
A14: 10 | B14: Canada | C14: 5
A15: 11 | B15: Russia | C15: 5
A16: 12 | B16: South Korea | C16: 5
... A54: 50 | B54: Qatar | C54: 5

Sheet Global Master Database
A1: Rank | B1: Company Name | C1: Country | D1: HQ City | E1: Industry | F1: Sector | G1: Company Type | H1: Founded Year | I1: CEO | J1: Official Website | K1: Business Description | L1: Main Products/Services | M1: Stock Exchange | N1: Ticker Symbol | O1: Annual Revenue (USD) | P1: Net Income (USD) | Q1: Market Cap (USD) | R1: Fortune Global 500 Rank | S1: Parent Company | T1: Data Source | U1: Verification Status | V1: Last Updated
A2: United States | B2: Apple Inc. | C2: 1 | D2: Cupertino, CA | E2: Technology | F2: Consumer Electronics | G2: Public | H2: 1976 | I2: Verification Pending | J2: https://www.apple.com | K2: Designs and sells consumer electronics, software, and services including iPhone, Mac, and iCloud. | L2: Designs and sells consumer electronics, software, and services including iPhone, Mac, and iCloud | M2: NASDAQ | N2: AAPL | O2: Verification Pending | P2: Verification Pending | Q2: Verification Pending | R2: Verification Pending | S2: N/A | T2: Company knowledge base (stable facts) | U2: Needs financial/leadership verification | V2: 2026-07-18
A3: United States | B3: Microsoft Corporation | C3: 2 | D3: Redmond, WA | E3: Technology | F3: Software & Cloud Computing | G3: Public | H3: 1975 | I3: Verification Pending | J3: https://www.microsoft.com | K3: Develops software, cloud services (Azure), and hardware including Windows and Office. | L3: Develops software, cloud services (Azure), and hardware including Windows and Office | M3: NASDAQ | N3: MSFT | O3: Verification Pending | P3: Verification Pending | Q3: Verification Pending | R3: Verification Pending | S3: N/A | T3: Company knowledge base (stable facts) | U3: Needs financial/leadership verification | V3: 2026-07-18
A4: United States | B4: Amazon.com, Inc. | C4: 3 | D4: Seattle, WA | E4: E-commerce/Cloud Computing | F4: Retail & Cloud Infrastructure | G4: Public | H4: 1994 | I4: Verification Pending | J4: https://www.amazon.com | K4: Global e-commerce and cloud computing (AWS) company. | L4: Global e-commerce and cloud computing (AWS) company | M4: NASDAQ | N4: AMZN | O4: Verification Pending | P4: Verification Pending | Q4: Verification Pending | R4: Verification Pending | S4: N/A | T4: Company knowledge base (stable facts) | U4: Needs financial/leadership verification | V4: 2026-07-18
A5: United States | B5: Alphabet Inc. (Google) | C5: 4 | D5: Mountain View, CA | E5: Technology | F5: Internet Services & AI | G5: Public | H5: 1998 | I5: Verification Pending | J5: https://abc.xyz | K5: Parent of Google; search, advertising, cloud, and AI research. | L5: Parent of Google; search, advertising, cloud, and AI research | M5: NASDAQ | N5: GOOGL | O5: Verification Pending | P5: Verification Pending | Q5: Verification Pending | R5: Verification Pending | S5: N/A | T5: Company knowledge base (stable facts) | U5: Needs financial/leadership verification | V5: 2026-07-18
A6: United States | B6: ExxonMobil | C6: 5 | D6: Spring, TX | E6: Oil & Gas | F6: Energy | G6: Public | H6: 1999 | I6: Verification Pending | J6: https://corporate.exxonmobil.com | K6: Integrated oil and gas exploration, production, and refining company. | L6: Integrated oil and gas exploration, production, and refining company | M6: NYSE | N6: XOM | O6: Verification Pending | P6: Verification Pending | Q6: Verification Pending | R6: Verification Pending | S6: N/A | T6: Company knowledge base (stable facts) | U6: Needs financial/leadership verification | V6: 2026-07-18
A7: United States | B7: JPMorgan Chase & Co. | C7: 6 | D7: New York, NY | E7: Banking | F7: Financial Services | G7: Public | H7: 1799 | I7: Verification Pending | J7: https://www.jpmorganchase.com | K7: Largest U.S. bank by assets, offering investment banking and consumer banking. | L7: Largest U | M7: NYSE | N7: JPM | O7: Verification Pending | P7: Verification Pending | Q7: Verification Pending | R7: Verification Pending | S7: N/A | T7: Company knowledge base (stable facts) | U7: Needs financial/leadership verification | V7: 2026-07-18
A8: United States | B8: Berkshire Hathaway | C8: 7 | D8: Omaha, NE | E8: Conglomerate/Insurance | F8: Financial Services | G8: Public | H8: 1839 | I8: Verification Pending | J8: https://www.berkshirehathaway.com | K8: Diversified holding company with insurance, rail, energy, and equity investments. | L8: Diversified holding company with insurance, rail, energy, and equity investments | M8: NYSE | N8: BRK.A | O8: Verification Pending | P8: Verification Pending | Q8: Verification Pending | R8: Verification Pending | S8: N/A | T8: Company knowledge base (stable facts) | U8: Needs financial/leadership verification | V8: 2026-07-18
A9: United States | B9: UnitedHealth Group | C9: 8 | D9: Minnetonka, MN | E9: Healthcare | F9: Health Insurance & Services | G9: Public | H9: 1977 | I9: Verification Pending | J9: https://www.unitedhealthgroup.com | K9: Largest U.S. health insurer and healthcare services provider. | L9: Largest U | M9: NYSE | N9: UNH | O9: Verification Pending | P9: Verification Pending | Q9: Verification Pending | R9: Verification Pending | S9: N/A | T9: Company knowledge base (stable facts) | U9: Needs financial/leadership verification | V9: 2026-07-18
A10: China | B10: State Grid Corporation of China | C10: 1 | D10: Beijing | E10: Utilities | F10: Electric Power Transmission | G10: State-Owned | H10: 2002 | I10: Verification Pending | J10: https://www.sgcc.com.cn | K10: World's largest electric utility, operating national grid infrastructure. | L10: World's largest electric utility, operating national grid infrastructure | M10: State-owned (not listed) | N10: N/A | O10: Verification Pending | P10: Verification Pending | Q10: Verification Pending | R10: Verification Pending | S10: N/A | T10: Company knowledge base (stable facts) | U10: Needs financial/leadership verification | V10: 2026-07-18
A11: China | B11: Sinopec Group | C11: 2 | D11: Beijing | E11: Oil & Gas | F11: Energy | G11: State-Owned | H11: 1998 | I11: Verification Pending | J11: https://www.sinopecgroup.com | K11: Integrated energy and chemical company; refining and petrochemicals. | L11: Integrated energy and chemical company; refining and petrochemicals | M11: SSE/HKEX | N11: 600028 | O11: Verification Pending | P11: Verification Pending | Q11: Verification Pending | R11: Verification Pending | S11: N/A | T11: Company knowledge base (stable facts) | U11: Needs financial/leadership verification | V11: 2026-07-18
A12: China | B12: PetroChina / CNPC | C12: 3 | D12: Beijing | E12: Oil & Gas | F12: Energy | G12: State-Owned | H12: 1999 | I12: Verification Pending | J12: https://www.petrochina.com.cn | K12: Major oil and gas exploration and production company. | L12: Major oil and gas exploration and production company | M12: SSE/HKEX | N12: 601857 | O12: Verification Pending | P12: Verification Pending | Q12: Verification Pending | R12: Verification Pending | S12: N/A | T12: Company knowledge base (stable facts) | U12: Needs financial/leadership verification | V12: 2026-07-18
A13: China | B13: Industrial and Commercial Bank of China (ICBC) | C13: 4 | D13: Beijing | E13: Banking | F13: Financial Services | G13: State-Owned | H13: 1984 | I13: Verification Pending | J13: https://www.icbc.com.cn | K13: World's largest bank by total assets. | L13: World's largest bank by total assets | M13: SSE/HKEX | N13: 601398 | O13: Verification Pending | P13: Verification Pending | Q13: Verification Pending | R13: Verification Pending | S13: N/A | T13: Company knowledge base (stable facts) | U13: Needs financial/leadership verification | V13: 2026-07-18
... A265: Qatar | B265: Qatar Airways | C265: 5 | D265: Doha | E265: Aviation | F265: Airlines | G265: State-Owned | H265: 1993 | I265: Verification Pending | J265: https://www.qatarairways.com | K265: Qatar's state-owned flag carrier, major global airline. | L265: Qatar's state-owned flag carrier, major global airline | M265: State-owned | N265: N/A | O265: Verification Pending | P265: Verification Pending | Q265: Verification Pending | R265: Verification Pending | S265: N/A | T265: Company knowledge base (stable facts) | U265: Needs financial/leadership verification | V265: 2026-07-18

Sheet United States
A1: Rank | B1: Company Name | C1: Country | D1: HQ City | E1: Industry | F1: Sector | G1: Company Type | H1: Founded Year | I1: CEO | J1: Official Website | K1: Business Description | L1: Main Products/Services | M1: Stock Exchange | N1: Ticker Symbol | O1: Annual Revenue (USD) | P1: Net Income (USD) | Q1: Market Cap (USD) | R1: Fortune Global 500 Rank | S1: Parent Company | T1: Data Source | U1: Verification Status | V1: Last Updated
A2: United States | B2: Apple Inc. | C2: 1 | D2: Cupertino, CA | E2: Technology | F2: Consumer Electronics | G2: Public | H2: 1976 | I2: Verification Pending | J2: https://www.apple.com | K2: Designs and sells consumer electronics, software, and services including iPhone, Mac, and iCloud. | L2: Designs and sells consumer electronics, software, and services including iPhone, Mac, and iCloud | M2: NASDAQ | N2: AAPL | O2: Verification Pending | P2: Verification Pending | Q2: Verification Pending | R2: Verification Pending | S2: N/A | T2: Company knowledge base (stable facts) | U2: Needs financial/leadership verification | V2: 2026-07-18
A3: United States | B3: Microsoft Corporation | C3: 2 | D3: Redmond, WA | E3: Technology | F3: Software & Cloud Computing | G3: Public | H3: 1975 | I3: Verification Pending | J3: https://www.microsoft.com | K3: Develops software, cloud services (Azure), and hardware including Windows and Office. | L3: Develops software, cloud services (Azure), and hardware including Windows and Office | M3: NASDAQ | N3: MSFT | O3: Verification Pending | P3: Verification Pending | Q3: Verification Pending | R3: Verification Pending | S3: N/A | T3: Company knowledge base (stable facts) | U3: Needs financial/leadership verification | V3: 2026-07-18
A4: United States | B4: Amazon.com, Inc. | C4: 3 | D4: Seattle, WA | E4: E-commerce/Cloud Computing | F4: Retail & Cloud Infrastructure | G4: Public | H4: 1994 | I4: Verification Pending | J4: https://www.amazon.com | K4: Global e-commerce and cloud computing (AWS) company. | L4: Global e-commerce and cloud computing (AWS) company | M4: NASDAQ | N4: AMZN | O4: Verification Pending | P4: Verification Pending | Q4: Verification Pending | R4: Verification Pending | S4: N/A | T4: Company knowledge base (stable facts) | U4: Needs financial/leadership verification | V4: 2026-07-18
A5: United States | B5: Alphabet Inc. (Google) | C5: 4 | D5: Mountain View, CA | E5: Technology | F5: Internet Services & AI | G5: Public | H5: 1998 | I5: Verification Pending | J5: https://abc.xyz | K5: Parent of Google; search, advertising, cloud, and AI research. | L5: Parent of Google; search, advertising, cloud, and AI research | M5: NASDAQ | N5: GOOGL | O5: Verification Pending | P5: Verification Pending | Q5: Verification Pending | R5: Verification Pending | S5: N/A | T5: Company knowledge base (stable facts) | U5: Needs financial/leadership verification | V5: 2026-07-18
A6: United States | B6: ExxonMobil | C6: 5 | D6: Spring, TX | E6: Oil & Gas | F6: Energy | G6: Public | H6: 1999 | I6: Verification Pending | J6: https://corporate.exxonmobil.com | K6: Integrated oil and gas exploration, production, and refining company. | L6: Integrated oil and gas exploration, production, and refining company | M6: NYSE | N6: XOM | O6: Verification Pending | P6: Verification Pending | Q6: Verification Pending | R6: Verification Pending | S6: N/A | T6: Company knowledge base (stable facts) | U6: Needs financial/leadership verification | V6: 2026-07-18
A7: United States | B7: JPMorgan Chase & Co. | C7: 6 | D7: New York, NY | E7: Banking | F7: Financial Services | G7: Public | H7: 1799 | I7: Verification Pending | J7: https://www.jpmorganchase.com | K7: Largest U.S. bank by assets, offering investment banking and consumer banking. | L7: Largest U | M7: NYSE | N7: JPM | O7: Verification Pending | P7: Verification Pending | Q7: Verification Pending | R7: Verification Pending | S7: N/A | T7: Company knowledge base (stable facts) | U7: Needs financial/leadership verification | V7: 2026-07-18
A8: United States | B8: Berkshire Hathaway | C8: 7 | D8: Omaha, NE | E8: Conglomerate/Insurance | F8: Financial Services | G8: Public | H8: 1839 | I8: Verification Pending | J8: https://www.berkshirehathaway.com | K8: Diversified holding company with insurance, rail, energy, and equity investments. | L8: Diversified holding company with insurance, rail, energy, and equity investments | M8: NYSE | N8: BRK.A | O8: Verification Pending | P8: Verification Pending | Q8: Verification Pending | R8: Verification Pending | S8: N/A | T8: Company knowledge base (stable facts) | U8: Needs financial/leadership verification | V8: 2026-07-18
A9: United States | B9: UnitedHealth Group | C9: 8 | D9: Minnetonka, MN | E9: Healthcare | F9: Health Insurance & Services | G9: Public | H9: 1977 | I9: Verification Pending | J9: https://www.unitedhealthgroup.com | K9: Largest U.S. health insurer and healthcare services provider. | L9: Largest U | M9: NYSE | N9: UNH | O9: Verification Pending | P9: Verification Pending | Q9: Verification Pending | R9: Verification Pending | S9: N/A | T9: Company knowledge base (stable facts) | U9: Needs financial/leadership verification | V9: 2026-07-18
A11: Note: | B11: Company identity, industry, HQ, founding year, and website are stable facts. 'Verification Pending' fields (CEO, revenue, net income, market cap, Fortune 500 rank) change frequently and require a live data-verification pass before use in analysis.

Sheet China
A1: Rank | B1: Company Name | C1: Country | D1: HQ City | E1: Industry | F1: Sector | G1: Company Type | H1: Founded Year | I1: CEO | J1: Official Website | K1: Business Description | L1: Main Products/Services | M1: Stock Exchange | N1: Ticker Symbol | O1: Annual Revenue (USD) | P1: Net Income (USD) | Q1: Market Cap (USD) | R1: Fortune Global 500 Rank | S1: Parent Company | T1: Data Source | U1: Verification Status | V1: Last Updated
A2: China | B2: State Grid Corporation of China | C2: 1 | D2: Beijing | E2: Utilities | F2: Electric Power Transmission | G2: State-Owned | H2: 2002 | I2: Verification Pending | J2: https://www.sgcc.com.cn | K2: World's largest electric utility, operating national grid infrastructure. | L2: World's largest electric utility, operating national grid infrastructure | M2: State-owned (not listed) | N2: N/A | O2: Verification Pending | P2: Verification Pending | Q2: Verification Pending | R2: Verification Pending | S2: N/A | T2: Company knowledge base (stable facts) | U2: Needs financial/leadership verification | V2: 2026-07-18
A3: China | B3: Sinopec Group | C3: 2 | D3: Beijing | E3: Oil & Gas | F3: Energy | G3: State-Owned | H3: 1998 | I3: Verification Pending | J3: https://www.sinopecgroup.com | K3: Integrated energy and chemical company; refining and petrochemicals. | L3: Integrated energy and chemical company; refining and petrochemicals | M3: SSE/HKEX | N3: 600028 | O3: Verification Pending | P3: Verification Pending | Q3: Verification Pending | R3: Verification Pending | S3: N/A | T3: Company knowledge base (stable facts) | U3: Needs financial/leadership verification | V3: 2026-07-18
A4: China | B4: PetroChina / CNPC | C4: 3 | D4: Beijing | E4: Oil & Gas | F4: Energy | G4: State-Owned | H4: 1999 | I4: Verification Pending | J4: https://www.petrochina.com.cn | K4: Major oil and gas exploration and production company. | L4: Major oil and gas exploration and production company | M4: SSE/HKEX | N4: 601857 | O4: Verification Pending | P4: Verification Pending | Q4: Verification Pending | R4: Verification Pending | S4: N/A | T4: Company knowledge base (stable facts) | U4: Needs financial/leadership verification | V4: 2026-07-18
A5: China | B5: Industrial and Commercial Bank of China (ICBC) | C5: 4 | D5: Beijing | E5: Banking | F5: Financial Services | G5: State-Owned | H5: 1984 | I5: Verification Pending | J5: https://www.icbc.com.cn | K5: World's largest bank by total assets. | L5: World's largest bank by total assets | M5: SSE/HKEX | N5: 601398 | O5: Verification Pending | P5: Verification Pending | Q5: Verification Pending | R5: Verification Pending | S5: N/A | T5: Company knowledge base (stable facts) | U5: Needs financial/leadership verification | V5: 2026-07-18
A6: China | B6: Huawei Technologies | C6: 5 | D6: Shenzhen | E6: Telecommunications/Technology | F6: Networking Equipment & Devices | G6: Private | H6: 1987 | I6: Verification Pending | J6: https://www.huawei.com | K6: Telecom equipment, smartphones, and 5G infrastructure provider. | L6: Telecom equipment, smartphones, and 5G infrastructure provider | M6: Private | N6: N/A | O6: Verification Pending | P6: Verification Pending | Q6: Verification Pending | R6: Verification Pending | S6: N/A | T6: Company knowledge base (stable facts) | U6: Needs financial/leadership verification | V6: 2026-07-18
A7: China | B7: Alibaba Group | C7: 6 | D7: Hangzhou | E7: E-commerce | F7: Internet Services | G7: Public | H7: 1999 | I7: Verification Pending | J7: https://www.alibabagroup.com | K7: E-commerce, cloud computing, and digital payments conglomerate. | L7: E-commerce, cloud computing, and digital payments conglomerate | M7: NYSE/HKEX | N7: BABA | O7: Verification Pending | P7: Verification Pending | Q7: Verification Pending | R7: Verification Pending | S7: N/A | T7: Company knowledge base (stable facts) | U7: Needs financial/leadership verification | V7: 2026-07-18
A8: China | B8: Tencent Holdings | C8: 7 | D8: Shenzhen | E8: Technology | F8: Internet & Gaming | G8: Public | H8: 1998 | I8: Verification Pending | J8: https://www.tencent.com | K8: Social media, gaming, and fintech (WeChat, gaming publishing). | L8: Social media, gaming, and fintech (WeChat, gaming publishing) | M8: HKEX | N8: 0700 | O8: Verification Pending | P8: Verification Pending | Q8: Verification Pending | R8: Verification Pending | S8: N/A | T8: Company knowledge base (stable facts) | U8: Needs financial/leadership verification | V8: 2026-07-18
A9: China | B9: China Construction Bank | C9: 8 | D9: Beijing | E9: Banking | F9: Financial Services | G9: State-Owned | H9: 1954 | I9: Verification Pending | J9: https://www.ccb.com | K9: One of China's 'Big Four' state-owned commercial banks. | L9: One of China's 'Big Four' state-owned commercial banks | M9: SSE/HKEX | N9: 601939 | O9: Verification Pending | P9: Verification Pending | Q9: Verification Pending | R9: Verification Pending | S9: N/A | T9: Company knowledge base (stable facts) | U9: Needs financial/leadership verification | V9: 2026-07-18
A11: Note: | B11: Company identity, industry, HQ, founding year, and website are stable facts. 'Verification Pending' fields (CEO, revenue, net income, market cap, Fortune 500 rank) change frequently and require a live data-verification pass before use in analysis.

Sheet Japan
A1: Rank | B1: Company Name | C1: Country | D1: HQ City | E1: Industry | F1: Sector | G1: Company Type | H1: Founded Year | I1: CEO | J1: Official Website | K1: Business Description | L1: Main Products/Services | M1: Stock Exchange | N1: Ticker Symbol | O1: Annual Revenue (USD) | P1: Net Income (USD) | Q1: Market Cap (USD) | R1: Fortune Global 500 Rank | S1: Parent Company | T1: Data Source | U1: Verification Status | V1: Last Updated
A2: Japan | B2: Toyota Motor Corporation | C2: 1 | D2: Toyota City, Aichi | E2: Automotive | F2: Auto Manufacturing | G2: Public | H2: 1937 | I2: Verification Pending | J2: https://global.toyota | K2: World's largest automaker by sales; also a leader in hybrid vehicle technology. | L2: World's largest automaker by sales; also a leader in hybrid vehicle technology | M2: TSE | N2: 7203 | O2: Verification Pending | P2: Verification Pending | Q2: Verification Pending | R2: Verification Pending | S2: N/A | T2: Company knowledge base (stable facts) | U2: Needs financial/leadership verification | V2: 2026-07-18
A3: Japan | B3: Sony Group Corporation | C3: 2 | D3: Tokyo | E3: Electronics/Entertainment | F3: Consumer Electronics & Media | G3: Public | H3: 1946 | I3: Verification Pending | J3: https://www.sony.com | K3: Consumer electronics, gaming (PlayStation), music, and film. | L3: Consumer electronics, gaming (PlayStation), music, and film | M3: TSE | N3: 6758 | O3: Verification Pending | P3: Verification Pending | Q3: Verification Pending | R3: Verification Pending | S3: N/A | T3: Company knowledge base (stable facts) | U3: Needs financial/leadership verification | V3: 2026-07-18
A4: Japan | B4: Mitsubishi UFJ Financial Group | C4: 3 | D4: Tokyo | E4: Banking | F4: Financial Services | G4: Public | H4: 2005 | I4: Verification Pending | J4: https://www.mufg.jp | K4: Japan's largest bank holding company. | L4: Japan's largest bank holding company | M4: TSE | N4: 8306 | O4: Verification Pending | P4: Verification Pending | Q4: Verification Pending | R4: Verification Pending | S4: N/A | T4: Company knowledge base (stable facts) | U4: Needs financial/leadership verification | V4: 2026-07-18
A5: Japan | B5: Honda Motor Co. | C5: 4 | D5: Tokyo | E5: Automotive | F5: Auto & Motorcycle Manufacturing | G5: Public | H5: 1948 | I5: Verification Pending | J5: https://global.honda | K5: Automobiles, motorcycles, and power equipment manufacturer. | L5: Automobiles, motorcycles, and power equipment manufacturer | M5: TSE | N5: 7267 | O5: Verification Pending | P5: Verification Pending | Q5: Verification Pending | R5: Verification Pending | S5: N/A | T5: Company knowledge base (stable facts) | U5: Needs financial/leadership verification | V5: 2026-07-18
A6: Japan | B6: SoftBank Group | C6: 5 | D6: Tokyo | E6: Telecommunications/Investment | F6: Technology Holding | G6: Public | H6: 1981 | I6: Verification Pending | J6: https://group.softbank | K6: Telecom carrier and technology investment conglomerate (Vision Fund). | L6: Telecom carrier and technology investment conglomerate (Vision Fund) | M6: TSE | N6: 9984 | O6: Verification Pending | P6: Verification Pending | Q6: Verification Pending | R6: Verification Pending | S6: N/A | T6: Company knowledge base (stable facts) | U6: Needs financial/leadership verification | V6: 2026-07-18
A7: Japan | B7: Keyence Corporation | C7: 6 | D7: Osaka | E7: Electronics | F7: Industrial Automation Sensors | G7: Public | H7: 1974 | I7: Verification Pending | J7: https://www.keyence.com | K7: Factory automation sensors and measurement systems. | L7: Factory automation sensors and measurement systems | M7: TSE | N7: 6861 | O7: Verification Pending | P7: Verification Pending | Q7: Verification Pending | R7: Verification Pending | S7: N/A | T7: Company knowledge base (stable facts) | U7: Needs financial/leadership verification | V7: 2026-07-18
A8: Japan | B8: Nippon Telegraph and Telephone (NTT) | C8: 7 | D8: Tokyo | E8: Telecommunications | F8: Telecom Services | G8: Public | H8: 1985 | I8: Verification Pending | J8: https://group.ntt | K8: Japan's largest telecommunications company. | L8: Japan's largest telecommunications company | M8: TSE | N8: 9432 | O8: Verification Pending | P8: Verification Pending | Q8: Verification Pending | R8: Verification Pending | S8: N/A | T8: Company knowledge base (stable facts) | U8: Needs financial/leadership verification | V8: 2026-07-18
A10: Note: | B10: Company identity, industry, HQ, founding year, and website are stable facts. 'Verification Pending' fields (CEO, revenue, net income, market cap, Fortune 500 rank) change frequently and require a live data-verification pass before use in analysis.

Sheet Germany
A1: Rank | B1: Company Name | C1: Country | D1: HQ City | E1: Industry | F1: Sector | G1: Company Type | H1: Founded Year | I1: CEO | J1: Official Website | K1: Business Description | L1: Main Products/Services | M1: Stock Exchange | N1: Ticker Symbol | O1: Annual Revenue (USD) | P1: Net Income (USD) | Q1: Market Cap (USD) | R1: Fortune Global 500 Rank | S1: Parent Company | T1: Data Source | U1: Verification Status | V1: Last Updated
A2: Germany | B2: Volkswagen Group | C2: 1 | D2: Wolfsburg | E2: Automotive | F2: Auto Manufacturing | G2: Public | H2: 1937 | I2: Verification Pending | J2: https://www.volkswagenag.com | K2: World's largest automaker by volume; owns Audi, Porsche, Skoda. | L2: World's largest automaker by volume; owns Audi, Porsche, Skoda | M2: FWB | N2: VOW3 | O2: Verification Pending | P2: Verification Pending | Q2: Verification Pending | R2: Verification Pending | S2: N/A | T2: Company knowledge base (stable facts) | U2: Needs financial/leadership verification | V2: 2026-07-18
A3: Germany | B3: Mercedes-Benz Group | C3: 2 | D3: Stuttgart | E3: Automotive | F3: Luxury Auto Manufacturing | G3: Public | H3: 1926 | I3: Verification Pending | J3: https://group.mercedes-benz.com | K3: Luxury automobiles and commercial vehicles manufacturer. | L3: Luxury automobiles and commercial vehicles manufacturer | M3: FWB | N3: MBG | O3: Verification Pending | P3: Verification Pending | Q3: Verification Pending | R3: Verification Pending | S3: N/A | T3: Company knowledge base (stable facts) | U3: Needs financial/leadership verification | V3: 2026-07-18
A4: Germany | B4: SAP SE | C4: 3 | D4: Walldorf | E4: Software | F4: Enterprise Software | G4: Public | H4: 1972 | I4: Verification Pending | J4: https://www.sap.com | K4: Enterprise resource planning (ERP) software leader. | L4: Enterprise resource planning (ERP) software leader | M4: FWB/NYSE | N4: SAP | O4: Verification Pending | P4: Verification Pending | Q4: Verification Pending | R4: Verification Pending | S4: N/A | T4: Company knowledge base (stable facts) | U4: Needs financial/leadership verification | V4: 2026-07-18
A5: Germany | B5: Siemens AG | C5: 4 | D5: Munich | E5: Industrial Manufacturing | F5: Industrial Automation & Infrastructure | G5: Public | H5: 1847 | I5: Verification Pending | J5: https://www.siemens.com | K5: Industrial automation, healthcare technology, and infrastructure conglomerate. | L5: Industrial automation, healthcare technology, and infrastructure conglomerate | M5: FWB | N5: SIE | O5: Verification Pending | P5: Verification Pending | Q5: Verification Pending | R5: Verification Pending | S5: N/A | T5: Company knowledge base (stable facts) | U5: Needs financial/leadership verification | V5: 2026-07-18
A6: Germany | B6: Allianz SE | C6: 5 | D6: Munich | E6: Insurance | F6: Financial Services | G6: Public | H6: 1890 | I6: Verification Pending | J6: https://www.allianz.com | K6: One of the world's largest insurance and asset management companies. | L6: One of the world's largest insurance and asset management companies | M6: FWB | N6: ALV | O6: Verification Pending | P6: Verification Pending | Q6: Verification Pending | R6: Verification Pending | S6: N/A | T6: Company knowledge base (stable facts) | U6: Needs financial/leadership verification | V6: 2026-07-18
A7: Germany | B7: BMW Group | C7: 6 | D7: Munich | E7: Automotive | F7: Luxury Auto Manufacturing | G7: Public | H7: 1916 | I7: Verification Pending | J7: https://www.bmwgroup.com | K7: Luxury automobiles and motorcycles manufacturer. | L7: Luxury automobiles and motorcycles manufacturer | M7: FWB | N7: BMW | O7: Verification Pending | P7: Verification Pending | Q7: Verification Pending | R7: Verification Pending | S7: N/A | T7: Company knowledge base (stable facts) | U7: Needs financial/leadership verification | V7: 2026-07-18
A8: Germany | B8: Deutsche Telekom | C8: 7 | D8: Bonn | E8: Telecommunications | F8: Telecom Services | G8: Public | H8: 1995 | I8: Verification Pending | J8: https://www.telekom.com | K8: Telecom carrier; majority owner of T-Mobile US. | L8: Telecom carrier; majority owner of T-Mobile US | M8: FWB | N8: DTE | O8: Verification Pending | P8: Verification Pending | Q8: Verification Pending | R8: Verification Pending | S8: N/A | T8: Company knowledge base (stable facts) | U8: Needs financial/leadership verification | V8: 2026-07-18
A10: Note: | B10: Company identity, industry, HQ, founding year, and website are stable facts. 'Verification Pending' fields (CEO, revenue, net income, market cap, Fortune 500 rank) change frequently and require a live data-verification pass before use in analysis.

Sheet India
A1: Rank | B1: Company Name | C1: Country | D1: HQ City | E1: Industry | F1: Sector | G1: Company Type | H1: Founded Year | I1: CEO | J1: Official Website | K1: Business Description | L1: Main Products/Services | M1: Stock Exchange | N1: Ticker Symbol | O1: Annual Revenue (USD) | P1: Net Income (USD) | Q1: Market Cap (USD) | R1: Fortune Global 500 Rank | S1: Parent Company | T1: Data Source | U1: Verification Status | V1: Last Updated
A2: India | B2: Reliance Industries | C2: 1 | D2: Mumbai | E2: Conglomerate | F2: Energy, Retail & Telecom | G2: Public | H2: 1966 | I2: Verification Pending | J2: https://www.ril.com | K2: Diversified conglomerate spanning petrochemicals, retail, and telecom (Jio). | L2: Diversified conglomerate spanning petrochemicals, retail, and telecom (Jio) | M2: NSE/BSE | N2: RELIANCE | O2: Verification Pending | P2: Verification Pending | Q2: Verification Pending | R2: Verification Pending | S2: N/A | T2: Company knowledge base (stable facts) | U2: Needs financial/leadership verification | V2: 2026-07-18
A3: India | B3: Tata Consultancy Services (TCS) | C3: 2 | D3: Mumbai | E3: Information Technology | F3: IT Services | G3: Public | H3: 1968 | I3: Verification Pending | J3: https://www.tcs.com | K3: Global IT services, consulting, and business solutions company. | L3: Global IT services, consulting, and business solutions company | M3: NSE/BSE | N3: TCS | O3: Verification Pending | P3: Verification Pending | Q3: Verification Pending | R3: Verification Pending | S3: N/A | T3: Company knowledge base (stable facts) | U3: Needs financial/leadership verification | V3: 2026-07-18
A4: India | B4: HDFC Bank | C4: 3 | D4: Mumbai | E4: Banking | F4: Financial Services | G4: Public | H4: 1994 | I4: Verification Pending | J4: https://www.hdfcbank.com | K4: India's largest private sector bank by assets. | L4: India's largest private sector bank by assets | M4: NSE/BSE | N4: HDFCBANK | O4: Verification Pending | P4: Verification Pending | Q4: Verification Pending | R4: Verification Pending | S4: N/A | T4: Company knowledge base (stable facts) | U4: Needs financial/leadership verification | V4: 2026-07-18
A5: India | B5: Infosys | C5: 4 | D5: Bengaluru | E5: Information Technology | F5: IT Services | G5: Public | H5: 1981 | I5: Verification Pending | J5: https://www.infosys.com | K5: Global IT consulting and outsourcing services company. | L5: Global IT consulting and outsourcing services company | M5: NSE/BSE | N5: INFY | O5: Verification Pending | P5: Verification Pending | Q5: Verification Pending | R5: Verification Pending | S5: N/A | T5: Company knowledge base (stable facts) | U5: Needs financial/leadership verification | V5: 2026-07-18
A6: India | B6: ICICI Bank | C6: 5 | D6: Mumbai | E6: Banking | F6: Financial Services | G6: Public | H6: 1994 | I6: Verification Pending | J6: https://www.icicibank.com | K6: Major private sector bank offering retail and corporate banking. | L6: Major private sector bank offering retail and corporate banking | M6: NSE/BSE | N6: ICICIBANK | O6: Verification Pending | P6: Verification Pending | Q6: Verification Pending | R6: Verification Pending | S6: N/A | T6: Company knowledge base (stable facts) | U6: Needs financial/leadership verification | V6: 2026-07-18
A7: India | B7: State Bank of India | C7: 6 | D7: Mumbai | E7: Banking | F7: Financial Services | G7: State-Owned | H7: 1955 | I7: Verification Pending | J7: https://www.sbi.co.in | K7: India's largest public sector bank. | L7: India's largest public sector bank | M7: NSE/BSE | N7: SBIN | O7: Verification Pending | P7: Verification Pending | Q7: Verification Pending | R7: Verification Pending | S7: N/A | T7: Company knowledge base (stable facts) | U7: Needs financial/leadership verification | V7: 2026-07-18
A8: India | B8: Adani Group | C8: 7 | D8: Ahmedabad | E8: Conglomerate | F8: Ports, Energy & Infrastructure | G8: Public | H8: 1988 | I8: Verification Pending | J8: https://www.adani.com | K8: Infrastructure conglomerate spanning ports, power, and renewables. | L8: Infrastructure conglomerate spanning ports, power, and renewables | M8: NSE/BSE | N8: ADANIENT | O8: Verification Pending | P8: Verification Pending | Q8: Verification Pending | R8: Verification Pending | S8: N/A | T8: Company knowledge base (stable facts) | U8: Needs financial/leadership verification | V8: 2026-07-18
A10: Note: | B10: Company identity, industry, HQ, founding year, and website are stable facts. 'Verification Pending' fields (CEO, revenue, net income, market cap, Fortune 500 rank) change frequently and require a live data-verification pass before use in analysis.

Sheet United Kingdom
A1: Rank | B1: Company Name | C1: Country | D1: HQ City | E1: Industry | F1: Sector | G1: Company Type | H1: Founded Year | I1: CEO | J1: Official Website | K1: Business Description | L1: Main Products/Services | M1: Stock Exchange | N1: Ticker Symbol | O1: Annual Revenue (USD) | P1: Net Income (USD) | Q1: Market Cap (USD) | R1: Fortune Global 500 Rank | S1: Parent Company | T1: Data Source | U1: Verification Status | V1: Last Updated
A2: United Kingdom | B2: Shell plc | C2: 1 | D2: London | E2: Oil & Gas | F2: Energy | G2: Public | H2: 1907 | I2: Verification Pending | J2: https://www.shell.com | K2: Global integrated oil, gas, and renewable energy company. | L2: Global integrated oil, gas, and renewable energy company | M2: LSE | N2: SHEL | O2: Verification Pending | P2: Verification Pending | Q2: Verification Pending | R2: Verification Pending | S2: N/A | T2: Company knowledge base (stable facts) | U2: Needs financial/leadership verification | V2: 2026-07-18
A3: United Kingdom | B3: HSBC Holdings | C3: 2 | D3: London | E3: Banking | F3: Financial Services | G3: Public | H3: 1865 | I3: Verification Pending | J3: https://www.hsbc.com | K3: One of the world's largest banking and financial services organizations. | L3: One of the world's largest banking and financial services organizations | M3: LSE | N3: HSBA | O3: Verification Pending | P3: Verification Pending | Q3: Verification Pending | R3: Verification Pending | S3: N/A | T3: Company knowledge base (stable facts) | U3: Needs financial/leadership verification | V3: 2026-07-18
A4: United Kingdom | B4: AstraZeneca | C4: 3 | D4: Cambridge | E4: Pharmaceuticals | F4: Biopharmaceuticals | G4: Public | H4: 1999 | I4: Verification Pending | J4: https://www.astrazeneca.com | K4: Global biopharmaceutical company focused on oncology and rare diseases. | L4: Global biopharmaceutical company focused on oncology and rare diseases | M4: LSE | N4: AZN | O4: Verification Pending | P4: Verification Pending | Q4: Verification Pending | R4: Verification Pending | S4: N/A | T4: Company knowledge base (stable facts) | U4: Needs financial/leadership verification | V4: 2026-07-18
A5: United Kingdom | B5: BP plc | C5: 4 | D5: London | E5: Oil & Gas | F5: Energy | G5: Public | H5: 1909 | I5: Verification Pending | J5: https://www.bp.com | K5: Integrated oil and gas company with growing low-carbon business. | L5: Integrated oil and gas company with growing low-carbon business | M5: LSE | N5: BP | O5: Verification Pending | P5: Verification Pending | Q5: Verification Pending | R5: Verification Pending | S5: N/A | T5: Company knowledge base (stable facts) | U5: Needs financial/leadership verification | V5: 2026-07-18
A6: United Kingdom | B6: Unilever | C6: 5 | D6: London | E6: Consumer Goods | F6: FMCG | G6: Public | H6: 1929 | I6: Verification Pending | J6: https://www.unilever.com | K6: Global consumer goods company - food, home and personal care brands. | L6: Global consumer goods company - food, home and personal care brands | M6: LSE | N6: ULVR | O6: Verification Pending | P6: Verification Pending | Q6: Verification Pending | R6: Verification Pending | S6: N/A | T6: Company knowledge base (stable facts) | U6: Needs financial/leadership verification | V6: 2026-07-18
A7: United Kingdom | B7: Diageo | C7: 6 | D7: London | E7: Beverages | F7: Alcoholic Beverages | G7: Public | H7: 1997 | I7: Verification Pending | J7: https://www.diageo.com | K7: World's largest producer of spirits, including Johnnie Walker and Guinness. | L7: World's largest producer of spirits, including Johnnie Walker and Guinness | M7: LSE | N7: DGE | O7: Verification Pending | P7: Verification Pending | Q7: Verification Pending | R7: Verification Pending | S7: N/A | T7: Company knowledge base (stable facts) | U7: Needs financial/leadership verification | V7: 2026-07-18
A9: Note: | B9: Company identity, industry, HQ, founding year, and website are stable facts. 'Verification Pending' fields (CEO, revenue, net income, market cap, Fortune 500 rank) change frequently and require a live data-verification pass before use in analysis.

Sheet France
A1: Rank | B1: Company Name | C1: Country | D1: HQ City | E1: Industry | F1: Sector | G1: Company Type | H1: Founded Year | I1: CEO | J1: Official Website | K1: Business Description | L1: Main Products/Services | M1: Stock Exchange | N1: Ticker Symbol | O1: Annual Revenue (USD) | P1: Net Income (USD) | Q1: Market Cap (USD) | R1: Fortune Global 500 Rank | S1: Parent Company | T1: Data Source | U1: Verification Status | V1: Last Updated
A2: France | B2: TotalEnergies | C2: 1 | D2: Paris | E2: Oil & Gas | F2: Energy | G2: Public | H2: 1924 | I2: Verification Pending | J2: https://totalenergies.com | K2: Multi-energy company spanning oil, gas, and renewables. | L2: Multi-energy company spanning oil, gas, and renewables | M2: Euronext Paris | N2: TTE | O2: Verification Pending | P2: Verification Pending | Q2: Verification Pending | R2: Verification Pending | S2: N/A | T2: Company knowledge base (stable facts) | U2: Needs financial/leadership verification | V2: 2026-07-18
A3: France | B3: LVMH | C3: 2 | D3: Paris | E3: Luxury Goods | F3: Fashion & Retail | G3: Public | H3: 1987 | I3: Verification Pending | J3: https://www.lvmh.com | K3: World's largest luxury goods conglomerate (Louis Vuitton, Dior, Moet Hennessy). | L3: World's largest luxury goods conglomerate (Louis Vuitton, Dior, Moet Hennessy) | M3: Euronext Paris | N3: MC | O3: Verification Pending | P3: Verification Pending | Q3: Verification Pending | R3: Verification Pending | S3: N/A | T3: Company knowledge base (stable facts) | U3: Needs financial/leadership verification | V3: 2026-07-18
A4: France | B4: L'Oreal | C4: 3 | D4: Clichy | E4: Consumer Goods | F4: Cosmetics | G4: Public | H4: 1909 | I4: Verification Pending | J4: https://www.loreal.com | K4: World's largest cosmetics and beauty company. | L4: World's largest cosmetics and beauty company | M4: Euronext Paris | N4: OR | O4: Verification Pending | P4: Verification Pending | Q4: Verification Pending | R4: Verification Pending | S4: N/A | T4: Company knowledge base (stable facts) | U4: Needs financial/leadership verification | V4: 2026-07-18
A5: France | B5: BNP Paribas | C5: 4 | D5: Paris | E5: Banking | F5: Financial Services | G5: Public | H5: 1848 | I5: Verification Pending | J5: https://www.bnpparibas.com | K5: One of the largest banks in the world by assets. | L5: One of the largest banks in the world by assets | M5: Euronext Paris | N5: BNP | O5: Verification Pending | P5: Verification Pending | Q5: Verification Pending | R5: Verification Pending | S5: N/A | T5: Company knowledge base (stable facts) | U5: Needs financial/leadership verification | V5: 2026-07-18
A6: France | B6: Airbus SE | C6: 5 | D6: Toulouse/Leiden | E6: Aerospace | F6: Aircraft Manufacturing | G6: Public | H6: 1970 | I6: Verification Pending | J6: https://www.airbus.com | K6: World's largest commercial aircraft manufacturer alongside Boeing. | L6: World's largest commercial aircraft manufacturer alongside Boeing | M6: Euronext Paris | N6: AIR | O6: Verification Pending | P6: Verification Pending | Q6: Verification Pending | R6: Verification Pending | S6: N/A | T6: Company knowledge base (stable facts) | U6: Needs financial/leadership verification | V6: 2026-07-18
A7: France | B7: Sanofi | C7: 6 | D7: Paris | E7: Pharmaceuticals | F7: Biopharmaceuticals | G7: Public | H7: 1973 | I7: Verification Pending | J7: https://www.sanofi.com | K7: Global pharmaceutical and healthcare company. | L7: Global pharmaceutical and healthcare company | M7: Euronext Paris | N7: SAN | O7: Verification Pending | P7: Verification Pending | Q7: Verification Pending | R7: Verification Pending | S7: N/A | T7: Company knowledge base (stable facts) | U7: Needs financial/leadership verification | V7: 2026-07-18
A9: Note: | B9: Company identity, industry, HQ, founding year, and website are stable facts. 'Verification Pending' fields (CEO, revenue, net income, market cap, Fortune 500 rank) change frequently and require a live data-verification pass before use in analysis.

Sheet Italy
A1: Rank | B1: Company Name | C1: Country | D1: HQ City | E1: Industry | F1: Sector | G1: Company Type | H1: Founded Year | I1: CEO | J1: Official Website | K1: Business Description | L1: Main Products/Services | M1: Stock Exchange | N1: Ticker Symbol | O1: Annual Revenue (USD) | P1: Net Income (USD) | Q1: Market Cap (USD) | R1: Fortune Global 500 Rank | S1: Parent Company | T1: Data Source | U1: Verification Status | V1: Last Updated
A2: Italy | B2: Eni S.p.A. | C2: 1 | D2: Rome | E2: Oil & Gas | F2: Energy | G2: Public | H2: 1953 | I2: Verification Pending | J2: https://www.eni.com | K2: Integrated energy company in oil, gas, and renewables. | L2: Integrated energy company in oil, gas, and renewables | M2: Borsa Italiana | N2: ENI | O2: Verification Pending | P2: Verification Pending | Q2: Verification Pending | R2: Verification Pending | S2: N/A | T2: Company knowledge base (stable facts) | U2: Needs financial/leadership verification | V2: 2026-07-18
A3: Italy | B3: Enel S.p.A. | C3: 2 | D3: Rome | E3: Utilities | F3: Electric Power | G3: Public | H3: 1962 | I3: Verification Pending | J3: https://www.enel.com | K3: Multinational electricity and gas utility, major renewables operator. | L3: Multinational electricity and gas utility, major renewables operator | M3: Borsa Italiana | N3: ENEL | O3: Verification Pending | P3: Verification Pending | Q3: Verification Pending | R3: Verification Pending | S3: N/A | T3: Company knowledge base (stable facts) | U3: Needs financial/leadership verification | V3: 2026-07-18
A4: Italy | B4: Intesa Sanpaolo | C4: 3 | D4: Turin | E4: Banking | F4: Financial Services | G4: Public | H4: 2007 | I4: Verification Pending | J4: https://group.intesasanpaolo.com | K4: Italy's largest banking group. | L4: Italy's largest banking group | M4: Borsa Italiana | N4: ISP | O4: Verification Pending | P4: Verification Pending | Q4: Verification Pending | R4: Verification Pending | S4: N/A | T4: Company knowledge base (stable facts) | U4: Needs financial/leadership verification | V4: 2026-07-18
A5: Italy | B5: UniCredit | C5: 4 | D5: Milan | E5: Banking | F5: Financial Services | G5: Public | H5: 1998 | I5: Verification Pending | J5: https://www.unicredit.eu | K5: Major pan-European commercial bank. | L5: Major pan-European commercial bank | M5: Borsa Italiana | N5: UCG | O5: Verification Pending | P5: Verification Pending | Q5: Verification Pending | R5: Verification Pending | S5: N/A | T5: Company knowledge base (stable facts) | U5: Needs financial/leadership verification | V5: 2026-07-18
A6: Italy | B6: Ferrari N.V. | C6: 5 | D6: Maranello | E6: Automotive | F6: Luxury Sports Cars | G6: Public | H6: 1939 | I6: Verification Pending | J6: https://corporate.ferrari.com | K6: Manufacturer of luxury sports cars and Formula 1 racing team. | L6: Manufacturer of luxury sports cars and Formula 1 racing team | M6: Borsa Italiana/NYSE | N6: RACE | O6: Verification Pending | P6: Verification Pending | Q6: Verification Pending | R6: Verification Pending | S6: N/A | T6: Company knowledge base (stable facts) | U6: Needs financial/leadership verification | V6: 2026-07-18
A8: Note: | B8: Company identity, industry, HQ, founding year, and website are stable facts. 'Verification Pending' fields (CEO, revenue, net income, market cap, Fortune 500 rank) change frequently and require a live data-verification pass before use in analysis.

Sheet Brazil
A1: Rank | B1: Company Name | C1: Country | D1: HQ City | E1: Industry | F1: Sector | G1: Company Type | H1: Founded Year | I1: CEO | J1: Official Website | K1: Business Description | L1: Main Products/Services | M1: Stock Exchange | N1: Ticker Symbol | O1: Annual Revenue (USD) | P1: Net Income (USD) | Q1: Market Cap (USD) | R1: Fortune Global 500 Rank | S1: Parent Company | T1: Data Source | U1: Verification Status | V1: Last Updated
A2: Brazil | B2: Petrobras | C2: 1 | D2: Rio de Janeiro | E2: Oil & Gas | F2: Energy | G2: State-Owned | H2: 1953 | I2: Verification Pending | J2: https://petrobras.com.br | K2: Brazil's state-controlled oil and gas company. | L2: Brazil's state-controlled oil and gas company | M2: B3/NYSE | N2: PETR4 | O2: Verification Pending | P2: Verification Pending | Q2: Verification Pending | R2: Verification Pending | S2: N/A | T2: Company knowledge base (stable facts) | U2: Needs financial/leadership verification | V2: 2026-07-18
A3: Brazil | B3: Vale S.A. | C3: 2 | D3: Rio de Janeiro | E3: Mining | F3: Metals & Mining | G3: Public | H3: 1942 | I3: Verification Pending | J3: https://www.vale.com | K3: World's largest producer of iron ore and nickel. | L3: World's largest producer of iron ore and nickel | M3: B3/NYSE | N3: VALE | O3: Verification Pending | P3: Verification Pending | Q3: Verification Pending | R3: Verification Pending | S3: N/A | T3: Company knowledge base (stable facts) | U3: Needs financial/leadership verification | V3: 2026-07-18
A4: Brazil | B4: Itau Unibanco | C4: 3 | D4: Sao Paulo | E4: Banking | F4: Financial Services | G4: Public | H4: 2008 | I4: Verification Pending | J4: https://www.itau.com.br | K4: Largest private bank in Latin America. | L4: Largest private bank in Latin America | M4: B3 | N4: ITUB4 | O4: Verification Pending | P4: Verification Pending | Q4: Verification Pending | R4: Verification Pending | S4: N/A | T4: Company knowledge base (stable facts) | U4: Needs financial/leadership verification | V4: 2026-07-18
A5: Brazil | B5: Banco Bradesco | C5: 4 | D5: Osasco | E5: Banking | F5: Financial Services | G5: Public | H5: 1943 | I5: Verification Pending | J5: https://www.bradesco.com.br | K5: One of Brazil's largest private banks. | L5: One of Brazil's largest private banks | M5: B3 | N5: BBDC4 | O5: Verification Pending | P5: Verification Pending | Q5: Verification Pending | R5: Verification Pending | S5: N/A | T5: Company knowledge base (stable facts) | U5: Needs financial/leadership verification | V5: 2026-07-18
A6: Brazil | B6: JBS S.A. | C6: 5 | D6: Sao Paulo | E6: Food & Beverage | F6: Meat Processing | G6: Public | H6: 1953 | I6: Verification Pending | J6: https://jbs.com.br | K6: World's largest meat processing company. | L6: World's largest meat processing company | M6: B3 | N6: JBSS3 | O6: Verification Pending | P6: Verification Pending | Q6: Verification Pending | R6: Verification Pending | S6: N/A | T6: Company knowledge base (stable facts) | U6: Needs financial/leadership verification | V6: 2026-07-18
A8: Note: | B8: Company identity, industry, HQ, founding year, and website are stable facts. 'Verification Pending' fields (CEO, revenue, net income, market cap, Fortune 500 rank) change frequently and require a live data-verification pass before use in analysis.

Sheet Canada
A1: Rank | B1: Company Name | C1: Country | D1: HQ City | E1: Industry | F1: Sector | G1: Company Type | H1: Founded Year | I1: CEO | J1: Official Website | K1: Business Description | L1: Main Products/Services | M1: Stock Exchange | N1: Ticker Symbol | O1: Annual Revenue (USD) | P1: Net Income (USD) | Q1: Market Cap (USD) | R1: Fortune Global 500 Rank | S1: Parent Company | T1: Data Source | U1: Verification Status | V1: Last Updated
A2: Canada | B2: Royal Bank of Canada | C2: 1 | D2: Toronto | E2: Banking | F2: Financial Services | G2: Public | H2: 1864 | I2: Verification Pending | J2: https://www.rbc.com | K2: Canada's largest bank by market capitalization. | L2: Canada's largest bank by market capitalization | M2: TSX/NYSE | N2: RY | O2: Verification Pending | P2: Verification Pending | Q2: Verification Pending | R2: Verification Pending | S2: N/A | T2: Company knowledge base (stable facts) | U2: Needs financial/leadership verification | V2: 2026-07-18
A3: Canada | B3: Toronto-Dominion Bank | C3: 2 | D3: Toronto | E3: Banking | F3: Financial Services | G3: Public | H3: 1955 | I3: Verification Pending | J3: https://www.td.com | K3: Major Canadian bank with large U.S. retail presence. | L3: Major Canadian bank with large U | M3: TSX/NYSE | N3: TD | O3: Verification Pending | P3: Verification Pending | Q3: Verification Pending | R3: Verification Pending | S3: N/A | T3: Company knowledge base (stable facts) | U3: Needs financial/leadership verification | V3: 2026-07-18
A4: Canada | B4: Enbridge | C4: 3 | D4: Calgary | E4: Oil & Gas | F4: Energy Infrastructure | G4: Public | H4: 1949 | I4: Verification Pending | J4: https://www.enbridge.com | K4: North America's largest energy pipeline infrastructure company. | L4: North America's largest energy pipeline infrastructure company | M4: TSX/NYSE | N4: ENB | O4: Verification Pending | P4: Verification Pending | Q4: Verification Pending | R4: Verification Pending | S4: N/A | T4: Company knowledge base (stable facts) | U4: Needs financial/leadership verification | V4: 2026-07-18
A5: Canada | B5: Canadian National Railway | C5: 4 | D5: Montreal | E5: Logistics | F5: Rail Transport | G5: Public | H5: 1919 | I5: Verification Pending | J5: https://www.cn.ca | K5: Major transcontinental freight railway. | L5: Major transcontinental freight railway | M5: TSX/NYSE | N5: CNR | O5: Verification Pending | P5: Verification Pending | Q5: Verification Pending | R5: Verification Pending | S5: N/A | T5: Company knowledge base (stable facts) | U5: Needs financial/leadership verification | V5: 2026-07-18
A6: Canada | B6: Suncor Energy | C6: 5 | D6: Calgary | E6: Oil & Gas | F6: Energy | G6: Public | H6: 1917 | I6: Verification Pending | J6: https://www.suncor.com | K6: Integrated oil sands energy company. | L6: Integrated oil sands energy company | M6: TSX/NYSE | N6: SU | O6: Verification Pending | P6: Verification Pending | Q6: Verification Pending | R6: Verification Pending | S6: N/A | T6: Company knowledge base (stable facts) | U6: Needs financial/leadership verification | V6: 2026-07-18
A8: Note: | B8: Company identity, industry, HQ, founding year, and website are stable facts. 'Verification Pending' fields (CEO, revenue, net income, market cap, Fortune 500 rank) change frequently and require a live data-verification pass before use in analysis.

Sheet Russia
A1: Rank | B1: Company Name | C1: Country | D1: HQ City | E1: Industry | F1: Sector | G1: Company Type | H1: Founded Year | I1: CEO | J1: Official Website | K1: Business Description | L1: Main Products/Services | M1: Stock Exchange | N1: Ticker Symbol | O1: Annual Revenue (USD) | P1: Net Income (USD) | Q1: Market Cap (USD) | R1: Fortune Global 500 Rank | S1: Parent Company | T1: Data Source | U1: Verification Status | V1: Last Updated
A2: Russia | B2: Gazprom | C2: 1 | D2: Moscow | E2: Oil & Gas | F2: Energy | G2: State-Owned | H2: 1989 | I2: Verification Pending | J2: https://www.gazprom.com | K2: World's largest natural gas extraction and pipeline company. | L2: World's largest natural gas extraction and pipeline company | M2: MOEX | N2: GAZP | O2: Verification Pending | P2: Verification Pending | Q2: Verification Pending | R2: Verification Pending | S2: N/A | T2: Company knowledge base (stable facts) | U2: Needs financial/leadership verification | V2: 2026-07-18
A3: Russia | B3: Rosneft | C3: 2 | D3: Moscow | E3: Oil & Gas | F3: Energy | G3: State-Owned | H3: 1993 | I3: Verification Pending | J3: https://www.rosneft.com | K3: Russia's largest oil producer. | L3: Russia's largest oil producer | M3: MOEX | N3: ROSN | O3: Verification Pending | P3: Verification Pending | Q3: Verification Pending | R3: Verification Pending | S3: N/A | T3: Company knowledge base (stable facts) | U3: Needs financial/leadership verification | V3: 2026-07-18
A4: Russia | B4: Sberbank | C4: 3 | D4: Moscow | E4: Banking | F4: Financial Services | G4: State-Owned | H4: 1841 | I4: Verification Pending | J4: https://www.sberbank.com | K4: Russia's largest bank. | L4: Russia's largest bank | M4: MOEX | N4: SBER | O4: Verification Pending | P4: Verification Pending | Q4: Verification Pending | R4: Verification Pending | S4: N/A | T4: Company knowledge base (stable facts) | U4: Needs financial/leadership verification | V4: 2026-07-18
A5: Russia | B5: Lukoil | C5: 4 | D5: Moscow | E5: Oil & Gas | F5: Energy | G5: Public | H5: 1991 | I5: Verification Pending | J5: https://www.lukoil.com | K5: Major privately-owned Russian oil and gas company. | L5: Major privately-owned Russian oil and gas company | M5: MOEX | N5: LKOH | O5: Verification Pending | P5: Verification Pending | Q5: Verification Pending | R5: Verification Pending | S5: N/A | T5: Company knowledge base (stable facts) | U5: Needs financial/leadership verification | V5: 2026-07-18
A6: Russia | B6: Norilsk Nickel | C6: 5 | D6: Moscow | E6: Mining | F6: Metals & Mining | G6: Public | H6: 1935 | I6: Verification Pending | J6: https://www.nornickel.com | K6: World's largest producer of refined nickel and palladium. | L6: World's largest producer of refined nickel and palladium | M6: MOEX | N6: GMKN | O6: Verification Pending | P6: Verification Pending | Q6: Verification Pending | R6: Verification Pending | S6: N/A | T6: Company knowledge base (stable facts) | U6: Needs financial/leadership verification | V6: 2026-07-18
